<?xml version="1.0"?>
<robot name="my_robot">

  <material name="blue">
    <color rgba="0.4 0.6 1.0 1.0"/>
  </material>
  <material name="grey">
    <color rgba="0.5 0.5 0.5 1.0"/>
  </material>
  <material name="red">
    <color rgba="1.0 0.2 0.2 1.0"/>
  </material>

  <link name="world" />
  <link name="base_link">
    <visual>
      <geometry>
        <cylinder length="0.05" radius="0.15"/>
      </geometry>
      <origin rpy="0 0 0" xyz="0 0 0.025"/>
      <material name="grey"/>
    </visual>
  </link>
  <joint name="world_to_base" type="fixed">
    <parent link="world"/><child link="base_link"/>
  </joint>

  <link name="link1">
    <visual>
      <geometry><cylinder length="0.05" radius="0.10"/></geometry>
      <material name="blue"/>
    </visual>
  </link>
  <joint name="joint1" type="revolute">
    <parent link="base_link"/><child link="link1"/>
    <origin xyz="0 0 0.150" rpy="0 0 0" />
    <axis xyz="0 0 1"/>
    <limit   effort="300" velocity="25.136"/>
  </joint>

  <link name="link2">
    <visual>
      <geometry><cylinder length="0.400" radius="0.06"/></geometry>
      <origin rpy="1.5708 0 0" xyz="0 0 0.200"/>
      <material name="grey"/>
    </visual>
  </link>
  <joint name="joint2" type="revolute">
    <parent link="link1"/><child link="link2"/>
    <origin xyz="0 0 0.0449" rpy="0 0 0" />
    <axis xyz="0 1 0"/>
    <limit lower="-1.7" upper="1.7" effort="300" velocity="25.136"/>
  </joint>

  <link name="link3">
    <visual>
        <geometry><sphere radius="0.07"/></geometry>
        <material name="blue"/>
    </visual>
  </link>
  <joint name="joint3" type="revolute">
    <parent link="link2"/><child link="link3"/>
    <origin xyz="0 0 0.400" rpy="0 0 0" />
    <axis xyz="0 1 0"/>
    <limit lower="-2.7" upper="2.7" effort="300" velocity="25.136"/>
  </joint>

  <link name="link4">
    <visual>
      <geometry><cylinder length="0.2605" radius="0.05"/></geometry>
      <origin rpy="1.5708 0 0" xyz="0 0 0.13025"/>
      <material name="grey"/>
    </visual>
  </link>
  <joint name="joint4" type="revolute">
    <parent link="link3"/><child link="link4"/>
    <origin xyz="0 0 0.0654" rpy="0 0 0" />
    <axis xyz="0 0 1"/>
    <limit lower="-3" upper="3" effort="28" velocity="25.136"/>
  </joint>

  <link name="link5">
   <visual>
       <geometry><sphere radius="0.06"/></geometry>
       <material name="blue"/>
   </visual>
  </link>
  <joint name="joint5" type="revolute">
    <parent link="link4"/><child link="link5"/>
    <origin xyz="0 0 0.2605" rpy="0 0 0" />
    <axis xyz="0 1 0"/>
    <limit lower="-2.094" upper="2.094" effort="28" velocity="25.136"/>
  </joint>

  <link name="link6">
    <visual>
      <geometry><cylinder length="0.074" radius="0.04"/></geometry>
      <origin rpy="1.5708 0 0" xyz="0 0 0.037"/>
      <material name="grey"/>
    </visual>
  </link>
  <joint name="joint6" type="revolute">
    <parent link="link5"/><child link="link6"/>
    <origin xyz="0 0 0.071" rpy="0 0 0" />
    <axis xyz="0 0 1"/>
    <limit lower="-2.094" upper="2.094" effort="28" velocity="25.136"/>
  </joint>

  <link name="tool0">
    <visual>
        <geometry><cylinder length="0.01" radius="0.05"/></geometry>
        <origin rpy="1.5708 0 0" xyz="0 0 0.005"/>
        <material name="red"/>
    </visual>
  </link>
  <joint name="link6_to_tool0" type="fixed">
    <parent link="link6"/> <child link="tool0"/>
    <origin xyz="0 0 0.074" rpy="0 0 0"/>
  </joint>

</robot>