<?xml version="1.0"?>
<robot name="ur10_from_dh">

  <link name="world" />

  <link name="base_link">
    <visual>
      <geometry>
        <cylinder length="0.05" radius="0.10"/>
      </geometry>
      <origin rpy="0 0 0" xyz="0 0 0.025"/>
      <material name="blue">
        <color rgba="0.4 0.6 1.0 1.0"/>
      </material>
    </visual>
  </link>
  <joint name="world_to_base" type="fixed">
    <parent link="world"/>
    <child link="base_link"/>
    <origin rpy="0 0 0" xyz="0 0 0"/>
  </joint>

  <link name="link1">
    <visual>
      <geometry>
        <cylinder length="0.07" radius="0.06"/>
      </geometry>
      <origin rpy="0 0 0" xyz="0 0 0"/>
      <material name="grey"/>
    </visual>
  </link>
  <joint name="joint1" type="revolute">
    <parent link="base_link"/>
    <child link="link1"/>
    <origin xyz="0 0 7.47" rpy="-1.5708 0 0" />
    <axis xyz="0 0 1"/>
    <limit lower="-6.28" upper="6.28" effort="150" velocity="3.14"/>
  </joint>

  <link name="link2">
    <visual>
      <geometry>
        <cylinder length="0.41" radius="0.06"/>
      </geometry>
      <origin rpy="0 1.5708 0" xyz="0.205 0 0"/>
      <material name="blue"/>
    </visual>
  </link>
  <joint name="joint2" type="revolute">
    <parent link="link1"/>
    <child link="link2"/>
    <origin xyz="41 0 0" rpy="0 0 0" />
    <axis xyz="0 0 1"/>
    <limit lower="-6.28" upper="6.28" effort="150" velocity="3.14"/>
  </joint>

  <link name="link3">
    <visual>
      <geometry>
        <cylinder length="0.05" radius="0.06"/>
      </geometry>
      <origin rpy="0 0 0" xyz="0 0 0"/>
      <material name="grey"/>
    </visual>
  </link>
  <joint name="joint3" type="revolute">
    <parent link="link2"/>
    <child link="link3"/>
    <origin xyz="0.95 0 0" rpy="1.5708 0 0" />
    <axis xyz="0 0 1"/>
    <limit lower="-6.28" upper="6.28" effort="150" velocity="3.14"/>
  </joint>

  <link name="link4">
    <visual>
      <geometry>
        <cylinder length="0.27" radius="0.04"/>
      </geometry>
      <origin rpy="0 1.5708 0" xyz="0.135 0 0"/>
      <material name="blue"/>
    </visual>
  </link>
  <joint name="joint4" type="revolute">
    <parent link="link3"/>
    <child link="link4"/>
    <origin xyz="0 0 26.94" rpy="1.5708 0 0" />
    <axis xyz="0 0 1"/>
    <limit lower="-6.28" upper="6.28" effort="28" velocity="3.14"/>
  </joint>

  <link name="link5">
    <visual>
      <geometry>
        <cylinder length="0.05" radius="0.04"/>
      </geometry>
      <origin rpy="0 0 0" xyz="0 0 0"/>
      <material name="grey"/>
    </visual>
  </link>
  <joint name="joint5" type="revolute">
    <parent link="link4"/>
    <child link="link5"/>
    <origin xyz="0 0 3" rpy="-1.5708 0 0" />
    <axis xyz="0 0 1"/>
    <limit lower="-6.28" upper="6.28" effort="28" velocity="3.14"/>
  </joint>

  <link name="link6">
    <visual>
      <geometry>
        <cylinder length="0.20" radius="0.04"/>
      </geometry>
      <origin rpy="0 0 0" xyz="0 0 0.10"/>
      <material name="blue"/>
    </visual>
  </link>
  <joint name="joint6" type="revolute">
    <parent link="link5"/>
    <child link="link6"/>
    <origin xyz="0 0 20" rpy="0 0 0" />
    <axis xyz="0 0 1"/>
    <limit lower="-6.28" upper="6.28" effort="28" velocity="3.14"/>
  </joint>

  <link name="tool0"/>
  <joint name="link6_to_tool0" type="fixed">
    <parent link="link6"/>
    <child link="tool0"/>
    <origin xyz="0 0 0.20" rpy="0 0 0"/>
  </joint>

</robot>